Workbook

Sheet 2YR Financials
A1: Category | B1: 2025 | C1: 2024 | D1: Notes-TM | E1: row
A2: REVENUES | B2: 981009.84 | C2: 1042552.6 | E2: 2
B3: 0 | E3: 3
B4: 0 | C4: 0 | E4: 4
A5: COST OF SALES | B5: 619177.45 | C5: 687544.96 | E5: 5
A6: Gross Profit | B6: =B2+B3+B4 - B5 -> 361832.39 | C6: =C2+C3+C4 - C5 -> 355007.59 | E6: 6
E7: 7
A8: EXPENSES Payroll expense | E8: 8
A9: Salaries and Wages | B9: 118120.38 | C9: 156517.41 | E9: 9
A10: Wage Remittances (WCB, EI, CPP) | B10: 12062.88 | C10: 14023.25 | E10: 10
A11: Bonuses Paid | B11: 25024.32 | C11: 25603.08 | E11: 11
A12: Employee Benefits | B12: 6407.38 | C12: 5942.29 | E12: 12
A13: Accounting & Legal | B13: 1740.62 | C13: 1710.69 | E13: 13
A14: Bookkeeping | B14: 6960 | C14: 6900 | E14: 14
A15: Advertising & Promotions | B15: 11309.27 | C15: 13546.14 | E15: 15
A16: Credit Card Fees | B16: 8004.21 | C16: 8831.65 | E16: 16
A17: Customs/Duty Expense | B17: 89.69 | C17: 0 | E17: 17
A18: Donations | B18: 4610.7 | C18: 3827.41 | E18: 18
A19: Grooming | B19: 130 | C19: 689.04 | E19: 19
A20: Insurance | B20: 2220.5 | C20: 3173 | E20: 20
... A35: Vehicle | B35: 6480.02 | C35: 6656.27 | E35: 35
A36: Total Expenses | B36: =SUM(B9:B35) -> 392824.74 | C36: =SUM(C9:C35) -> 447581.59 | E36: 36
A37: COGS | B37: =B5 -> 619177.45 | C37: =C5 -> 687544.96 | E37: 37
A38: NET INCOME (LOSS) | B38: =SUM(B2-B37-B36) -> -30992.35 | C38: =SUM(C2-C37-C36) -> -92574 | E38: 38 | H38: =SUM(H36:H37) -> 0
A40: Equipment Value | B40: 0 | C40: 0

Sheet Normalized Calculations
A1: 2025 Normalized Financials -Insert Company Name & Date | H1: 2024 Normalized Financials - Insert Company Name & Date
B2: YE 2025 July 31, 2025 | C2: YE 2025 Normalized | D2: Notes | I2: 2024 Year End | J2: YE 2024 Normalized | K2: Notes - TM | M2: Notes
A3: REVENUE - SALES | B3: ='2YR Financials'!B2 -> 981009.84 | C3: 981009.84 | H3: REVENUE - SALES | I3: ='2YR Financials'!C2 -> 1042552.6 | J3: =I3 -> 1042552.6
B4: 0 | C4: 0 | J4: 0
B5: ='2YR Financials'!B4 -> 0 | C5: 0 | J5: 0
A6: ='2YR Financials'!A5 -> COST OF SALES | B6: ='2YR Financials'!B5 -> 619177.45 | C6: 619177.45 | H6: COST OF SALES | I6: ='2YR Financials'!C5 -> 687544.96 | J6: =I6 -> 687544.96
A7: ='2YR Financials'!A6 -> Gross Profit | B7: ='2YR Financials'!B6 -> 361832.39 | C7: 361832.39 | H7: Gross Profit | I7: ='2YR Financials'!C6 -> 355007.59 | J7: =I7 -> 355007.59
A9: EXPENSES | H9: EXPENSES
A10: ='2YR Financials'!A9 -> Salaries and Wages | B10: ='2YR Financials'!B9 -> 118120.38 | D10: Tammy to completed | H10: Salaries and Wages | I10: ='2YR Financials'!C9 -> 156517.41 | M10: tammy to Complete
A11: ='2YR Financials'!A10 -> Wage Remittances (WCB, EI, CPP) | B11: ='2YR Financials'!B10 -> 12062.88 | H11: Wage Remittances (WCB, EI, CPP) | I11: ='2YR Financials'!C10 -> 14023.25
A12: ='2YR Financials'!A11 -> Bonuses Paid | B12: ='2YR Financials'!B11 -> 25024.32 | H12: Bonuses Paid | I12: ='2YR Financials'!C11 -> 25603.08
A13: ='2YR Financials'!A12 -> Employee Benefits | B13: ='2YR Financials'!B12 -> 6407.38 | E13: =B13*40% -> 2562.952 | H13: Employee Benefits | I13: ='2YR Financials'!C12 -> 5942.29
A14: ='2YR Financials'!A13 -> Accounting & Legal | B14: ='2YR Financials'!B13 -> 1740.62 | H14: Accounting & Legal | I14: ='2YR Financials'!C13 -> 1710.69
A15: ='2YR Financials'!A14 -> Bookkeeping | B15: ='2YR Financials'!B14 -> 6960 | H15: Bookkeeping | I15: ='2YR Financials'!C14 -> 6900
A16: ='2YR Financials'!A15 -> Advertising & Promotions | B16: ='2YR Financials'!B15 -> 11309.27 | H16: Advertising & Promotions | I16: ='2YR Financials'!C15 -> 13546.14
A17: ='2YR Financials'!A16 -> Credit Card Fees | B17: ='2YR Financials'!B16 -> 8004.21 | H17: Credit Card Fees | I17: ='2YR Financials'!C16 -> 8831.65
A18: ='2YR Financials'!A17 -> Customs/Duty Expense | B18: ='2YR Financials'!B17 -> 89.69 | H18: Customs/Duty Expense | I18: ='2YR Financials'!C17 -> 0
A19: ='2YR Financials'!A18 -> Donations | B19: ='2YR Financials'!B18 -> 4610.7 | H19: Donations | I19: ='2YR Financials'!C18 -> 3827.41
A20: ='2YR Financials'!A19 -> Grooming | B20: ='2YR Financials'!B19 -> 130 | H20: Grooming | I20: ='2YR Financials'!C19 -> 689.04
A21: ='2YR Financials'!A20 -> Insurance | B21: ='2YR Financials'!B20 -> 2220.5 | H21: Insurance | I21: ='2YR Financials'!C20 -> 3173
A22: ='2YR Financials'!A21 -> Interest & Bank Charges | B22: ='2YR Financials'!B21 -> 1746.04 | H22: Interest & Bank Charges | I22: ='2YR Financials'!C21 -> 1718.64
A23: ='2YR Financials'!A22 -> Interest on LTD | B23: ='2YR Financials'!B22 -> 11391.89 | H23: Interest on LTD | I23: ='2YR Financials'!C22 -> 15762.81
A24: ='2YR Financials'!A23 -> Janitorial & Cleaning | B24: ='2YR Financials'!B23 -> 3415.32 | H24: Janitorial & Cleaning | I24: ='2YR Financials'!C23 -> 2658.48
A25: ='2YR Financials'!A24 -> Meals & Entertainment | B25: ='2YR Financials'!B24 -> 2192.73 | H25: Meals & Entertainment | I25: ='2YR Financials'!C24 -> 2490.88
... A36: ='2YR Financials'!A35 -> Vehicle | B36: ='2YR Financials'!B35 -> 6480.02 | H36: Vehicle | I36: ='2YR Financials'!C35 -> 6656.27
A37: Amortization / Depreciation | B37: 0 | H37: Amortization / Depreciation | I37: 0
A39: TOTAL | B39: =SUM(B10:B36) -> 392824.74 | C39: =SUM(C10:C37) -> 0 | H39: TOTAL | I39: ='2YR Financials'!C36 -> 447581.59
A40: COGS | B40: =B6 -> 619177.45 | C40: =C6 -> 619177.45 | H40: COGS | I40: =I6 -> 687544.96
A41: INCOME FROM OPERATIONS | B41: ='2YR Financials'!B38 -> -30992.35 | C41: =SUM(B7-C39) -> 361832.39 | H41: INCOME FROM OPERATIONS | I41: ='2YR Financials'!C38 -> -92574
A43: SDE Multiples | B43: Normalized Net | C43: 2.44 | D43: 2.94
A44: Average SDE Multiple Range: | B44: =C41 -> 361832.39 | C44: =B44*2.44 -> 882871.03 | D44: =B44*2.94 -> 1063787.2
A46: Inventory (wholesale) | B46: 86000 | C46: =B46 -> 86000 | D46: 86000
A47: Long term assets (Balance of Franchise Fee) | B47: 15000 | C47: 15000 | D47: 15000 | E47: ** | H47: Opened 2021
A48: Furniture, Fixtures, Equipment (FFE) - approx
A49: SDE Calculation + FFE and Inventory | C49: =SUM(C44:C48) -> 983871.03 | D49: =SUM(D44:D48) -> 1164787.2
A51: SDE Multiples | B51: Normalized Net | D51: 2.44 - 2.94
A52: Normalized Net | B52: =B44 -> 361832.39 | C52: SDE | D52: =B52*2.94 -> 1063787.2
A54: Furniture, Fixtures, Equipment (FFE) - approx | B54: 0 | D54: 0
A55: Inventory Wholesale | B55: 86000 | D55: 86000 | E55: **
A56: Long term Assets | B56: 15000 | D56: 15000 | H56: opened 2021
...
